<?xml version="1.0" encoding="utf-8"?>
<!-- This URDF was automatically created by SolidWorks to URDF Exporter! Originally created by Stephen Brawner (brawner@gmail.com) 
     Commit Version: 1.6.0-4-g7f85cfe  Build Version: 1.6.7995.38578
     For more information, please see http://wiki.ros.org/sw_urdf_exporter -->
<robot
  name="URDF_Final">
  <link
    name="base_link">
    <inertial>
      <origin
        xyz="-0.0215960012359151 1.98791973552836E-06 0.0473021509469852"
        rpy="0 0 0" />
      <mass
        value="1.62077206884196" />
      <inertia
        ixx="0.00729270388671559"
        ixy="4.50156743156905E-07"
        ixz="3.84454764398596E-05"
        iyy="0.0101769705459758"
        iyz="-1.58240720112386E-08"
        izz="0.0170963594420367" />
    </inertial>
    <visual>
      <origin
        xyz="0 0 0"
        rpy="-1.5708 0 0" />
      <geometry>
        <mesh
          filename="package://simulacion_ri/meshes/base_link.STL" />
      </geometry>
      <material
        name="">
        <color
          rgba="0.501960784313725 0 0.501960784313725 1" />
      </material>
    </visual>
    <collision>
      <origin
        xyz="0 0 0"
        rpy="-1.5708 0 0" />
      <geometry>
        <mesh
          filename="package://simulacion_ri/meshes/base_link.STL" />
      </geometry>
    </collision>
  </link>
  <link
    name="rueda_delante_izquierda_link">
    <inertial>
      <origin
        xyz="4.42360843788681E-09 -0.0114569553320259 -1.80991133816311E-08"
        rpy="0 0 0" />
      <mass
        value="0.166945648004187" />
      <inertia
        ixx="6.72930244970336E-05"
        ixy="-7.76816141684829E-13"
        ixz="-1.0816505579685E-09"
        iyy="0.000113206411586097"
        iyz="3.12188080606579E-12"
        izz="6.72960681931953E-05" />
    </inertial>
    <visual>
      <origin
        xyz="0 0 0"
        rpy="-1.5708 0 0" />
      <geometry>
        <mesh
          filename="package://simulacion_ri/meshes/rueda_delante_izquierda_link.STL" />
      </geometry>
      <material
        name="">
        <color
          rgba="0.792156862745098 0.819607843137255 0.933333333333333 1" />
      </material>
    </visual>
    <collision>
      <origin
        xyz="0 0 0"
        rpy="-1.5708 0 0" />
      <geometry>
        <mesh
          filename="package://simulacion_ri/meshes/rueda_delante_izquierda_link.STL" />
      </geometry>
    </collision>
  </link>
  <joint
    name="rueda_delante_izquierda_joint"
    type="continuous">
    <origin
      xyz="0.090145 0.14065 0.0125"
      rpy="0 0 0" />
    <parent
      link="base_link" />
    <child
      link="rueda_delante_izquierda_link" />
    <axis
      xyz="0 1 0" />
  </joint>
  <link
    name="rueda_delante_derecha_link">
    <inertial>
      <origin
        xyz="-1.85934702912061E-08 0.0114569553321121 -1.31549013696053E-09"
        rpy="0 0 0" />
      <mass
        value="0.166945647961675" />
      <inertia
        ixx="6.72964134163344E-05"
        ixy="-3.23034935191085E-12"
        ixz="5.95387395892094E-12"
        iyy="0.000113206411571408"
        iyz="-2.40053575325456E-13"
        izz="6.72926792591386E-05" />
    </inertial>
    <visual>
      <origin
        xyz="0 0 0"
        rpy="-1.5708 0 0" />
      <geometry>
        <mesh
          filename="package://simulacion_ri/meshes/rueda_delante_derecha_link.STL" />
      </geometry>
      <material
        name="">
        <color
          rgba="0.792156862745098 0.819607843137255 0.933333333333333 1" />
      </material>
    </visual>
    <collision>
      <origin
        xyz="0 0 0"
        rpy="-1.5708 0 0" />
      <geometry>
        <mesh
          filename="package://simulacion_ri/meshes/rueda_delante_derecha_link.STL" />
      </geometry>
    </collision>
  </link>
  <joint
    name="rueda_delante_derecha_joint"
    type="continuous">
    <origin
      xyz="0.090145 -0.14075 0.0125"
      rpy="0 0 0" />
    <parent
      link="base_link" />
    <child
      link="rueda_delante_derecha_link" />
    <axis
      xyz="0 1 0" />
  </joint>
  <link
    name="rueda_trasera_izquierda_link">
    <inertial>
      <origin
        xyz="-1.57372198050787E-08 -0.0114569553319947 -9.9716666000782E-09"
        rpy="0 0 0" />
      <mass
        value="0.166945648020152" />
      <inertia
        ixx="6.72951027113786E-05"
        ixy="2.69912050916349E-12"
        ixz="1.78225702684723E-09"
        iyy="0.000113206411591613"
        iyz="1.72380905063917E-12"
        izz="6.72939899843943E-05" />
    </inertial>
    <visual>
      <origin
        xyz="0 0 0"
        rpy="-1.5708 0 0" />
      <geometry>
        <mesh
          filename="package://simulacion_ri/meshes/rueda_trasera_izquierda_link.STL" />
      </geometry>
      <material
        name="">
        <color
          rgba="0.792156862745098 0.819607843137255 0.933333333333333 1" />
      </material>
    </visual>
    <collision>
      <origin
        xyz="0 0 0"
        rpy="-1.5708 0 0" />
      <geometry>
        <mesh
          filename="package://simulacion_ri/meshes/rueda_trasera_izquierda_link.STL" />
      </geometry>
    </collision>
  </link>
  <joint
    name="rueda_trasera_izquierda_joint"
    type="continuous">
    <origin
      xyz="-0.10109 0.14075 0.0125"
      rpy="0 0 0" />
    <parent
      link="base_link" />
    <child
      link="rueda_trasera_izquierda_link" />
    <axis
      xyz="0 1 0" />
  </joint>
  <link
    name="rueda_trasera_derecha_link">
    <inertial>
      <origin
        xyz="-1.85762422943991E-08 0.0114569553320164 -1.45158656275624E-09"
        rpy="0 0 0" />
      <mass
        value="0.16694564800895" />
      <inertia
        ixx="6.72964131425014E-05"
        ixy="-3.19798414980567E-12"
        ixz="3.25408794534319E-11"
        iyy="0.000113206411587756"
        iyz="-2.4682772153087E-13"
        izz="6.72926795493964E-05" />
    </inertial>
    <visual>
      <origin
        xyz="0 0 0"
        rpy="-1.5708 0 0" />
      <geometry>
        <mesh
          filename="package://simulacion_ri/meshes/rueda_trasera_derecha_link.STL" />
      </geometry>
      <material
        name="">
        <color
          rgba="0.792156862745098 0.819607843137255 0.933333333333333 1" />
      </material>
    </visual>
    <collision>
      <origin
        xyz="0 0 0"
        rpy="-1.5708 0 0" />
      <geometry>
        <mesh
          filename="package://simulacion_ri/meshes/rueda_trasera_derecha_link.STL" />
      </geometry>
    </collision>
  </link>
  <joint
    name="rueda_trasera_derecha_joint"
    type="continuous">
    <origin
      xyz="-0.10109 -0.14075 0.0125"
      rpy="0 0 0" />
    <parent
      link="base_link" />
    <child
      link="rueda_trasera_derecha_link" />
    <axis
      xyz="0 1 0" />
  </joint>
  <link
    name="laser">
    <inertial>
      <origin
        xyz="0.00512745596438566 0.000591552344835304 -0.0195507847870178"
        rpy="0 0 0" />
      <mass
        value="0.141654473640087" />
      <inertia
        ixx="5.69097097753618E-05"
        ixy="-2.87900344417994E-07"
        ixz="1.24753616532662E-05"
        iyy="8.93215448552512E-05"
        iyz="-7.21857208026095E-07"
        izz="0.000108702097721123" />
    </inertial>
    <visual>
      <origin
        xyz="0 0 0"
        rpy="-1.5708 0 0" />
      <geometry>
        <mesh
          filename="package://simulacion_ri/meshes/lidar_link.STL" />
      </geometry>
      <material
        name="">
        <color
          rgba="0.211764705882353 0.211764705882353 0.203921568627451 1" />
      </material>
    </visual>
    <collision>
      <origin
        xyz="0 0 0"
        rpy="-1.5708 0 0" />
      <geometry>
        <mesh
          filename="package://simulacion_ri/meshes/lidar_link.STL" />
      </geometry>
    </collision>
  </link>
  <joint
    name="laser_joint"
    type="fixed">
    <origin
      xyz="-0.05388 -3.5032E-05 0.17"
      rpy="0 0 0" />
    <parent
      link="base_link" />
    <child
      link="laser" />
    <axis
      xyz="0 0 0" />
  </joint>
</robot>